[2023-10-05T13:25:40.035+0000] {processor.py:157} INFO - Started process (PID=50) to work on /opt/airflow/dags/update_file.py
[2023-10-05T13:41:13.620+0000] {processor.py:157} INFO - Started process (PID=92) to work on /opt/airflow/dags/update_file.py
[2023-10-05T13:41:13.622+0000] {processor.py:829} INFO - Processing file /opt/airflow/dags/update_file.py for tasks to queue
[2023-10-05T13:41:13.627+0000] {logging_mixin.py:151} INFO - [2023-10-05T13:41:13.626+0000] {dagbag.py:539} INFO - Filling up the DagBag from /opt/airflow/dags/update_file.py
[2023-10-05T13:41:14.724+0000] {logging_mixin.py:151} INFO - [2023-10-05T13:41:14.715+0000] {dagbag.py:347} ERROR - Failed to import: /opt/airflow/dags/update_file.py
Traceback (most recent call last):
  File "/home/airflow/.local/lib/python3.8/site-packages/airflow/models/dagbag.py", line 343, in parse
    loader.exec_module(new_module)
  File "<frozen importlib._bootstrap_external>", line 843, in exec_module
  File "<frozen importlib._bootstrap>", line 219, in _call_with_frames_removed
  File "/opt/airflow/dags/update_file.py", line 14, in <module>
    dag = DAG(
  File "/home/airflow/.local/lib/python3.8/site-packages/airflow/models/dag.py", line 458, in __init__
    raise TypeError("default_args must be a dict")
TypeError: default_args must be a dict
[2023-10-05T13:41:14.726+0000] {processor.py:841} WARNING - No viable dags retrieved from /opt/airflow/dags/update_file.py
[2023-10-05T13:41:15.546+0000] {processor.py:179} INFO - Processing /opt/airflow/dags/update_file.py took 1.933 seconds
[2023-10-05T13:44:16.810+0000] {processor.py:157} INFO - Started process (PID=44) to work on /opt/airflow/dags/update_file.py
[2023-10-05T13:44:16.865+0000] {processor.py:829} INFO - Processing file /opt/airflow/dags/update_file.py for tasks to queue
[2023-10-05T13:44:16.870+0000] {logging_mixin.py:151} INFO - [2023-10-05T13:44:16.869+0000] {dagbag.py:539} INFO - Filling up the DagBag from /opt/airflow/dags/update_file.py
[2023-10-05T13:44:17.807+0000] {logging_mixin.py:151} INFO - [2023-10-05T13:44:17.801+0000] {dagbag.py:347} ERROR - Failed to import: /opt/airflow/dags/update_file.py
Traceback (most recent call last):
  File "/home/airflow/.local/lib/python3.8/site-packages/airflow/models/dagbag.py", line 343, in parse
    loader.exec_module(new_module)
  File "<frozen importlib._bootstrap_external>", line 843, in exec_module
  File "<frozen importlib._bootstrap>", line 219, in _call_with_frames_removed
  File "/opt/airflow/dags/update_file.py", line 14, in <module>
    dag = DAG(
  File "/home/airflow/.local/lib/python3.8/site-packages/airflow/models/dag.py", line 458, in __init__
    raise TypeError("default_args must be a dict")
TypeError: default_args must be a dict
[2023-10-05T13:44:17.808+0000] {processor.py:841} WARNING - No viable dags retrieved from /opt/airflow/dags/update_file.py
[2023-10-05T13:44:18.154+0000] {processor.py:179} INFO - Processing /opt/airflow/dags/update_file.py took 1.392 seconds
[2023-10-05T14:20:04.977+0000] {processor.py:157} INFO - Started process (PID=50) to work on /opt/airflow/dags/update_file.py
[2023-10-05T14:20:06.037+0000] {processor.py:829} INFO - Processing file /opt/airflow/dags/update_file.py for tasks to queue
[2023-10-05T14:20:14.343+0000] {logging_mixin.py:151} INFO - [2023-10-05T14:20:08.066+0000] {dagbag.py:539} INFO - Filling up the DagBag from /opt/airflow/dags/update_file.py
[2023-10-05T14:21:00.060+0000] {logging_mixin.py:151} INFO - [2023-10-05T14:21:00.059+0000] {timeout.py:68} ERROR - Process timed out, PID: 50
[2023-10-05T14:21:12.856+0000] {logging_mixin.py:151} INFO - [2023-10-05T14:21:01.139+0000] {dagbag.py:347} ERROR - Failed to import: /opt/airflow/dags/update_file.py
Traceback (most recent call last):
  File "/home/airflow/.local/lib/python3.8/site-packages/airflow/models/dagbag.py", line 343, in parse
    loader.exec_module(new_module)
  File "<frozen importlib._bootstrap_external>", line 839, in exec_module
  File "<frozen importlib._bootstrap_external>", line 988, in get_code
  File "<frozen importlib._bootstrap_external>", line 1078, in _cache_bytecode
  File "<frozen importlib._bootstrap_external>", line 1103, in set_data
  File "<frozen importlib._bootstrap_external>", line 186, in _write_atomic
  File "/home/airflow/.local/lib/python3.8/site-packages/airflow/dag_processing/manager.py", line 470, in _exit_gracefully
    self.log.debug("Current Stacktrace is: %s", "\n".join(map(str, inspect.stack())))
  File "/usr/local/lib/python3.8/inspect.py", line 1526, in stack
    return getouterframes(sys._getframe(1), context)
  File "/usr/local/lib/python3.8/inspect.py", line 1503, in getouterframes
    frameinfo = (frame,) + getframeinfo(frame, context)
  File "/usr/local/lib/python3.8/inspect.py", line 1477, in getframeinfo
    lines, lnum = findsource(frame)
  File "/usr/local/lib/python3.8/inspect.py", line 792, in findsource
    module = getmodule(object, file)
  File "/usr/local/lib/python3.8/inspect.py", line 744, in getmodule
    for modname, module in sys.modules.copy().items():
  File "/home/airflow/.local/lib/python3.8/site-packages/airflow/utils/timeout.py", line 69, in handle_timeout
    raise AirflowTaskTimeout(self.error_message)
airflow.exceptions.AirflowTaskTimeout: DagBag import timeout for /opt/airflow/dags/update_file.py after 30.0s.
Please take a look at these docs to improve your DAG import time:
* https://airflow.apache.org/docs/apache-airflow/2.7.1/best-practices.html#top-level-python-code
* https://airflow.apache.org/docs/apache-airflow/2.7.1/best-practices.html#reducing-dag-complexity, PID: 50
[2023-10-05T14:21:12.907+0000] {processor.py:841} WARNING - No viable dags retrieved from /opt/airflow/dags/update_file.py
